Workbook

Sheet NORMATIVOS
B1: Consolidado = 🟩 Proyeccion = 🟦 En Proceso = 🟨 No Adquirido = 🟥 | C1: Angel Babun | D1: Felix Mogollon
A2: PISO
A3: POSICIONES BÁSICAS Y FUERZA | B3: Postura de pie firme | C3: En proceso | D3: En proceso | E3: Proyección | F3: Proyección | G3: Proyección | H3: Proyección | I3: Proyección | J3: Proyección | K3: Proyección | L3: Proyección | M3: Proyección | N3: Proyección | O3: Proyección | P3: Proyección | Q3: Proyección | R3: Proyección | S3: Proyección | T3: Proyección | U3: Proyección | V3: Proyección | W3: Proyección | X3: Proyección | Y3: Proyección | Z3: Proyección
B4: Parado de hombros | C4: Consolidado | D4: En proceso | E4: Proyección | F4: Proyección | G4: Proyección | H4: Proyección | I4: Proyección | J4: Proyección | K4: Proyección | L4: Proyección | M4: Proyección | N4: Proyección | O4: Proyección | P4: Proyección | Q4: Proyección | R4: Proyección | S4: Proyección | T4: Proyección | U4: Proyección | V4: Proyección | W4: Proyección | X4: Proyección | Y4: Proyección | Z4: Proyección
B5: Parado de antebrazos | C5: Consolidado | D5: Consolidado | E5: Proyección | F5: Proyección | G5: Proyección | H5: Proyección | I5: Proyección | J5: Proyección | K5: Proyección | L5: Proyección | M5: Proyección | N5: Proyección | O5: Proyección | P5: Proyección | Q5: Proyección | R5: Proyección | S5: Proyección | T5: Proyección | U5: Proyección | V5: Proyección | W5: Proyección | X5: Proyección | Y5: Proyección | Z5: Proyección
B6: Parado de cabeza | C6: Consolidado | D6: Consolidado | E6: Proyección | F6: Proyección | G6: Proyección | H6: Proyección | I6: Proyección | J6: Proyección | K6: Proyección | L6: Proyección | M6: Proyección | N6: Proyección | O6: Proyección | P6: Proyección | Q6: Proyección | R6: Proyección | S6: Proyección | T6: Proyección | U6: Proyección | V6: Proyección | W6: Proyección | X6: Proyección | Y6: Proyección | Z6: Proyección
B7: Parado de manos en apoyo | C7: Consolidado | D7: En proceso | E7: Proyección | F7: Proyección | G7: Proyección | H7: Proyección | I7: Proyección | J7: Proyección | K7: Proyección | L7: Proyección | M7: Proyección | N7: Proyección | O7: Proyección | P7: Proyección | Q7: Proyección | R7: Proyección | S7: Proyección | T7: Proyección | U7: Proyección | V7: Proyección | W7: Proyección | X7: Proyección | Y7: Proyección | Z7: Proyección
B8: Parado de Manos | C8: En proceso | D8: En proceso | E8: Proyección | F8: Proyección | G8: Proyección | H8: Proyección | I8: Proyección | J8: Proyección | K8: Proyección | L8: Proyección | M8: Proyección | N8: Proyección | O8: Proyección | P8: Proyección | Q8: Proyección | R8: Proyección | S8: Proyección | T8: Proyección | U8: Proyección | V8: Proyección | W8: Proyección | X8: Proyección | Y8: Proyección | Z8: Proyección
B9: Split | C9: En proceso | D9: En proceso | E9: Proyección | F9: Proyección | G9: Proyección | H9: Proyección | I9: Proyección | J9: Proyección | K9: Proyección | L9: Proyección | M9: Proyección | N9: Proyección | O9: Proyección | P9: Proyección | Q9: Proyección | R9: Proyección | S9: Proyección | T9: Proyección | U9: Proyección | V9: Proyección | W9: Proyección | X9: Proyección | Y9: Proyección | Z9: Proyección
B10: Squat | C10: En proceso | D10: En proceso | E10: Proyección | F10: Proyección | G10: Proyección | H10: Proyección | I10: Proyección | J10: Proyección | K10: Proyección | L10: Proyección | M10: Proyección | N10: Proyección | O10: Proyección | P10: Proyección | Q10: Proyección | R10: Proyección | S10: Proyección | T10: Proyección | U10: Proyección | V10: Proyección | W10: Proyección | X10: Proyección | Y10: Proyección | Z10: Proyección
B11: Equilibrio a un pie (arabesca) | C11: Consolidado | D11: Consolidado | E11: Proyección | F11: Proyección | G11: Proyección | H11: Proyección | I11: Proyección | J11: Proyección | K11: Proyección | L11: Proyección | M11: Proyección | N11: Proyección | O11: Proyección | P11: Proyección | Q11: Proyección | R11: Proyección | S11: Proyección | T11: Proyección | U11: Proyección | V11: Proyección | W11: Proyección | X11: Proyección | Y11: Proyección | Z11: Proyección
B12: L sit | C12: Consolidado | D12: Consolidado | E12: Proyección | F12: Proyección | G12: Proyección | H12: Proyección | I12: Proyección | J12: Proyección | K12: Proyección | L12: Proyección | M12: Proyección | N12: Proyección | O12: Proyección | P12: Proyección | Q12: Proyección | R12: Proyección | S12: Proyección | T12: Proyección | U12: Proyección | V12: Proyección | W12: Proyección | X12: Proyección | Y12: Proyección | Z12: Proyección
B13: Sustentación en Arco | C13: Consolidado | D13: Consolidado | E13: Proyección | F13: Proyección | G13: Proyección | H13: Proyección | I13: Proyección | J13: Proyección | K13: Proyección | L13: Proyección | M13: Proyección | N13: Proyección | O13: Proyección | P13: Proyección | Q13: Proyección | R13: Proyección | S13: Proyección | T13: Proyección | U13: Proyección | V13: Proyección | W13: Proyección | X13: Proyección | Y13: Proyección | Z13: Proyección
B14: Soporte en escuadra endo | C14: Consolidado | D14: Consolidado | E14: Proyección | F14: Proyección | G14: Proyección | H14: Proyección | I14: Proyección | J14: Proyección | K14: Proyección | L14: Proyección | M14: Proyección | N14: Proyección | O14: Proyección | P14: Proyección | Q14: Proyección | R14: Proyección | S14: Proyección | T14: Proyección | U14: Proyección | V14: Proyección | W14: Proyección | X14: Proyección | Y14: Proyección | Z14: Proyección
B15: Kato de fuerza | C15: En proceso | D15: En proceso | E15: Proyección | F15: Proyección | G15: Proyección | H15: Proyección | I15: Proyección | J15: Proyección | K15: Proyección | L15: Proyección | M15: Proyección | N15: Proyección | O15: Proyección | P15: Proyección | Q15: Proyección | R15: Proyección | S15: Proyección | T15: Proyección | U15: Proyección | V15: Proyección | W15: Proyección | X15: Proyección | Y15: Proyección | Z15: Proyección
B16: Rodada Kato | C16: Consolidado | D16: En proceso | E16: Proyección | F16: Proyección | G16: Proyección | H16: Proyección | I16: Proyección | J16: Proyección | K16: Proyección | L16: Proyección | M16: Proyección | N16: Proyección | O16: Proyección | P16: Proyección | Q16: Proyección | R16: Proyección | S16: Proyección | T16: Proyección | U16: Proyección | V16: Proyección | W16: Proyección | X16: Proyección | Y16: Proyección | Z16: Proyección
A17: ACROBATICO HACÍA DELANTE | B17: Rodada adelanté | C17: Consolidado | D17: Consolidado | E17: Proyección | F17: Proyección | G17: Proyección | H17: Proyección | I17: Proyección | J17: Proyección | K17: Proyección | L17: Proyección | M17: Proyección | N17: Proyección | O17: Proyección | P17: Proyección | Q17: Proyección | R17: Proyección | S17: Proyección | T17: Proyección | U17: Proyección | V17: Proyección | W17: Proyección | X17: Proyección | Y17: Proyección | Z17: Proyección
B18: Vuelta de carro | C18: Consolidado | D18: Consolidado | E18: Proyección | F18: Proyección | G18: Proyección | H18: Proyección | I18: Proyección | J18: Proyección | K18: Proyección | L18: Proyección | M18: Proyección | N18: Proyección | O18: Proyección | P18: Proyección | Q18: Proyección | R18: Proyección | S18: Proyección | T18: Proyección | U18: Proyección | V18: Proyección | W18: Proyección | X18: Proyección | Y18: Proyección | Z18: Proyección
B19: Redondilla | C19: Consolidado | D19: Consolidado | E19: Proyección | F19: Proyección | G19: Proyección | H19: Proyección | I19: Proyección | J19: Proyección | K19: Proyección | L19: Proyección | M19: Proyección | N19: Proyección | O19: Proyección | P19: Proyección | Q19: Proyección | R19: Proyección | S19: Proyección | T19: Proyección | U19: Proyección | V19: Proyección | W19: Proyección | X19: Proyección | Y19: Proyección | Z19: Proyección
B20: Resorte a 2 pies | C20: Consolidado | D20: Consolidado | E20: Proyección | F20: Proyección | G20: Proyección | H20: Proyección | I20: Proyección | J20: Proyección | K20: Proyección | L20: Proyección | M20: Proyección | N20: Proyección | O20: Proyección | P20: Proyección | Q20: Proyección | R20: Proyección | S20: Proyección | T20: Proyección | U20: Proyección | V20: Proyección | W20: Proyección | X20: Proyección | Y20: Proyección | Z20: Proyección
B21: Resorte a 1 pie | C21: Consolidado | D21: Consolidado | E21: Proyección | F21: Proyección | G21: Proyección | H21: Proyección | I21: Proyección | J21: Proyección | K21: Proyección | L21: Proyección | M21: Proyección | N21: Proyección | O21: Proyección | P21: Proyección | Q21: Proyección | R21: Proyección | S21: Proyección | T21: Proyección | U21: Proyección | V21: Proyección | W21: Proyección | X21: Proyección | Y21: Proyección | Z21: Proyección
B22: Mortal adelante en C | C22: Consolidado | D22: Consolidado | E22: Proyección | F22: Proyección | G22: Proyección | H22: Proyección | I22: Proyección | J22: Proyección | K22: Proyección | L22: Proyección | M22: Proyección | N22: Proyección | O22: Proyección | P22: Proyección | Q22: Proyección | R22: Proyección | S22: Proyección | T22: Proyección | U22: Proyección | V22: Proyección | W22: Proyección | X22: Proyección | Y22: Proyección | Z22: Proyección
B23: Resorte 1 a 2 | C23: Consolidado | D23: Consolidado | E23: Proyección | F23: Proyección | G23: Proyección | H23: Proyección | I23: Proyección | J23: Proyección | K23: Proyección | L23: Proyección | M23: Proyección | N23: Proyección | O23: Proyección | P23: Proyección | Q23: Proyección | R23: Proyección | S23: Proyección | T23: Proyección | U23: Proyección | V23: Proyección | W23: Proyección | X23: Proyección | Y23: Proyección | Z23: Proyección
B24: Mortal adelante en V | C24: En proceso | D24: En proceso | E24: Proyección | F24: Proyección | G24: Proyección | H24: Proyección | I24: Proyección | J24: Proyección | K24: Proyección | L24: Proyección | M24: Proyección | N24: Proyección | O24: Proyección | P24: Proyección | Q24: Proyección | R24: Proyección | S24: Proyección | T24: Proyección | U24: Proyección | V24: Proyección | W24: Proyección | X24: Proyección | Y24: Proyección | Z24: Proyección
B25: Mortal extendido | C25: En proceso | D25: En proceso | E25: Proyección | F25: Proyección | G25: Proyección | H25: Proyección | I25: Proyección | J25: Proyección | K25: Proyección | L25: Proyección | M25: Proyección | N25: Proyección | O25: Proyección | P25: Proyección | Q25: Proyección | R25: Proyección | S25: Proyección | T25: Proyección | U25: Proyección | V25: Proyección | W25: Proyección | X25: Proyección | Y25: Proyección | Z25: Proyección
B26: Mortal rebote mortal | C26: Consolidado | D26: Consolidado | E26: Proyección | F26: Proyección | G26: Proyección | H26: Proyección | I26: Proyección | J26: Proyección | K26: Proyección | L26: Proyección | M26: Proyección | N26: Proyección | O26: Proyección | P26: Proyección | Q26: Proyección | R26: Proyección | S26: Proyección | T26: Proyección | U26: Proyección | V26: Proyección | W26: Proyección | X26: Proyección | Y26: Proyección | Z26: Proyección
B27: Doble mortal en C adelanté | C27: Proyección | D27: Proyección | E27: Proyección | F27: Proyección | G27: Proyección | H27: Proyección | I27: Proyección | J27: Proyección | K27: Proyección | L27: Proyección | M27: Proyección | N27: Proyección | O27: Proyección | P27: Proyección | Q27: Proyección | R27: Proyección | S27: Proyección | T27: Proyección | U27: Proyección | V27: Proyección | W27: Proyección | X27: Proyección | Y27: Proyección | Z27: Proyección
A28: ACROBATICO HACÍA ATRÁS | B28: Rodada atras | C28: Consolidado | D28: Consolidado | E28: Proyección | F28: Proyección | G28: Proyección | H28: Proyección | I28: Proyección | J28: Proyección | K28: Proyección | L28: Proyección | M28: Proyección | N28: Proyección | O28: Proyección | P28: Proyección | Q28: Proyección | R28: Proyección | S28: Proyección | T28: Proyección | U28: Proyección | V28: Proyección | W28: Proyección | X28: Proyección | Y28: Proyección | Z28: Proyección
B29: Rodada atrás a parado de manos | C29: Consolidado | D29: Consolidado | E29: Proyección | F29: Proyección | G29: Proyección | H29: Proyección | I29: Proyección | J29: Proyección | K29: Proyección | L29: Proyección | M29: Proyección | N29: Proyección | O29: Proyección | P29: Proyección | Q29: Proyección | R29: Proyección | S29: Proyección | T29: Proyección | U29: Proyección | V29: Proyección | W29: Proyección | X29: Proyección | Y29: Proyección | Z29: Proyección
B30: Flic flac | C30: Consolidado | D30: En proceso | E30: Proyección | F30: Proyección | G30: Proyección | H30: Proyección | I30: Proyección | J30: Proyección | K30: Proyección | L30: Proyección | M30: Proyección | N30: Proyección | O30: Proyección | P30: Proyección | Q30: Proyección | R30: Proyección | S30: Proyección | T30: Proyección | U30: Proyección | V30: Proyección | W30: Proyección | X30: Proyección | Y30: Proyección | Z30: Proyección
B31: Doble flic | C31: Consolidado | D31: En proceso | E31: Proyección | F31: Proyección | G31: Proyección | H31: Proyección | I31: Proyección | J31: Proyección | K31: Proyección | L31: Proyección | M31: Proyección | N31: Proyección | O31: Proyección | P31: Proyección | Q31: Proyección | R31: Proyección | S31: Proyección | T31: Proyección | U31: Proyección | V31: Proyección | W31: Proyección | X31: Proyección | Y31: Proyección | Z31: Proyección
B32: Mortal atras en C desde Redondilla | C32: Consolidado | D32: Consolidado | E32: Proyección | F32: Proyección | G32: Proyección | H32: Proyección | I32: Proyección | J32: Proyección | K32: Proyección | L32: Proyección | M32: Proyección | N32: Proyección | O32: Proyección | P32: Proyección | Q32: Proyección | R32: Proyección | S32: Proyección | T32: Proyección | U32: Proyección | V32: Proyección | W32: Proyección | X32: Proyección | Y32: Proyección | Z32: Proyección
B33: Mortal atras en C desde Flic flac | C33: En proceso | D33: En proceso | E33: Proyección | F33: Proyección | G33: Proyección | H33: Proyección | I33: Proyección | J33: Proyección | K33: Proyección | L33: Proyección | M33: Proyección | N33: Proyección | O33: Proyección | P33: Proyección | Q33: Proyección | R33: Proyección | S33: Proyección | T33: Proyección | U33: Proyección | V33: Proyección | W33: Proyección | X33: Proyección | Y33: Proyección | Z33: Proyección
B34: Mortal en V atras | C34: En proceso | D34: En proceso | E34: Proyección | F34: Proyección | G34: Proyección | H34: Proyección | I34: Proyección | J34: Proyección | K34: Proyección | L34: Proyección | M34: Proyección | N34: Proyección | O34: Proyección | P34: Proyección | Q34: Proyección | R34: Proyección | S34: Proyección | T34: Proyección | U34: Proyección | V34: Proyección | W34: Proyección | X34: Proyección | Y34: Proyección | Z34: Proyección
B35: Mortal extendido atras | C35: En proceso | D35: En proceso | E35: Proyección | F35: Proyección | G35: Proyección | H35: Proyección | I35: Proyección | J35: Proyección | K35: Proyección | L35: Proyección | M35: Proyección | N35: Proyección | O35: Proyección | P35: Proyección | Q35: Proyección | R35: Proyección | S35: Proyección | T35: Proyección | U35: Proyección | V35: Proyección | W35: Proyección | X35: Proyección | Y35: Proyección | Z35: Proyección
B36: Power flic (Tempo) | C36: En proceso | D36: En proceso | E36: Proyección | F36: Proyección | G36: Proyección | H36: Proyección | I36: Proyección | J36: Proyección | K36: Proyección | L36: Proyección | M36: Proyección | N36: Proyección | O36: Proyección | P36: Proyección | Q36: Proyección | R36: Proyección | S36: Proyección | T36: Proyección | U36: Proyección | V36: Proyección | W36: Proyección | X36: Proyección | Y36: Proyección | Z36: Proyección
B37: Doble mortal atrás en C | C37: Proyección | D37: Proyección | E37: Proyección | F37: Proyección | G37: Proyección | H37: Proyección | I37: Proyección | J37: Proyección | K37: Proyección | L37: Proyección | M37: Proyección | N37: Proyección | O37: Proyección | P37: Proyección | Q37: Proyección | R37: Proyección | S37: Proyección | T37: Proyección | U37: Proyección | V37: Proyección | W37: Proyección | X37: Proyección | Y37: Proyección | Z37: Proyección
A38: ACROBATICO CON GIRO | B38: Mortal extendido atras con 1/2 giro | C38: En proceso | D38: En proceso | E38: Proyección | F38: Proyección | G38: Proyección | H38: Proyección | I38: Proyección | J38: Proyección | K38: Proyección | L38: Proyección | M38: Proyección | N38: Proyección | O38: Proyección | P38: Proyección | Q38: Proyección | R38: Proyección | S38: Proyección | T38: Proyección | U38: Proyección | V38: Proyección | W38: Proyección | X38: Proyección | Y38: Proyección | Z38: Proyección
B39: Mortal extendido atras con un giro | C39: En proceso | D39: En proceso | E39: Proyección | F39: Proyección | G39: Proyección | H39: Proyección | I39: Proyección | J39: Proyección | K39: Proyección | L39: Proyección | M39: Proyección | N39: Proyección | O39: Proyección | P39: Proyección | Q39: Proyección | R39: Proyección | S39: Proyección | T39: Proyección | U39: Proyección | V39: Proyección | W39: Proyección | X39: Proyección | Y39: Proyección | Z39: Proyección
B40: Mortal agrupado adelanté con 1/2 giro | C40: En proceso | D40: En proceso | E40: Proyección | F40: Proyección | G40: Proyección | H40: Proyección | I40: Proyección | J40: Proyección | K40: Proyección | L40: Proyección | M40: Proyección | N40: Proyección | O40: Proyección | P40: Proyección | Q40: Proyección | R40: Proyección | S40: Proyección | T40: Proyección | U40: Proyección | V40: Proyección | W40: Proyección | X40: Proyección | Y40: Proyección | Z40: Proyección
...

Sheet FICHA DEL ATLETA
A1: FICHA INDIVIDUAL DE EVALUACIÓN
A3: Atleta: | B3: Angel Babun
A5: RESUMEN | D5: Aparato | E5: Consolidado | F5: En proceso | G5: Proyección | H5: % dominio
A6: Elementos evaluados | B6: =INDEX(CONSOLIDADO!$B$4:$B$5,MATCH($B$3,CONSOLIDADO!$A$4:$A$5,0)) -> 264 | D6: POSICIONES BÁSICAS Y FUERZA | E6: =--(INDEX(NORMATIVOS!$C$3:$Z$3,1,MATCH($B$3,NORMATIVOS!$C$1:$Z$1,0))="Consolidado")+--(INDEX(NORMATIVOS!$C$4:$Z$4,1,MATCH($B$3,NORMATIVOS!$C$1:$Z$1,0))="Consolidado")+--(INDEX(NORMATIVOS!$C$5:$Z$5,1,MATCH($B$3,NORMATIVOS!$C$1:$Z$1,0))="Consolidado")+--(INDEX(NORMATIVOS!$C$6:$Z$6,1,MATCH($B$3,NORMATIVOS!$C$1:$Z$1,0))="Consolidado")+--(INDEX(NORMATIVOS!$C$7:$Z$7,1,MATCH($B$3,NORMATIVOS!$C$1:$Z$1,0))="Consolidado")+--(INDEX(NORMATIVOS!$C$8:$Z$8,1,MATCH($B$3,NORMATIVOS!$C$1:$Z$1,0))="Consolidado")+--(INDEX(NORMATIVOS!$C$9:$Z$9,1,MATCH($B$3,NORMATIVOS!$C$1:$Z$1,0))="Consolidado")+--(INDEX(NORMATIVOS!$C$10:$Z$10,1,MATCH($B$3,NORMATIVOS!$C$1:$Z$1,0))="Consolidado")+--(INDEX(NORMATIVOS!$C$11:$Z$11,1,MATCH($B$3,NORMATIVOS!$C$1:$Z$1,0))="Consolidado")+--(INDEX(NORMATIVOS!$C$12:$Z$12,1,MATCH($B$3,NORMATIVOS!$C$1:$Z$1,0))="Consolidado")+--(INDEX(NORMATIVOS!$C$13:$Z$13,1,MATCH($B$3,NORMATIVOS!$C$1:$Z$1,0))="Consolidado")+--(INDEX(NORMATIVOS!$C$14:$Z$14,1,MATCH($B$3,NORMATIVOS!$C$1:$Z$1,0))="Consolidado")+--(INDEX(NORMATIVOS!$C$15:$Z$15,1,MATCH($B$3,NORMATIVOS!$C$1:$Z$1,0))="Consolidado")+--(INDEX(NORMATIVOS!$C$16:$Z$16,1,MATCH($B$3,NORMATIVOS!$C$1:$Z$1,0))="Consolidado") -> 9 | F6: =--(INDEX(NORMATIVOS!$C$3:$Z$3,1,MATCH($B$3,NORMATIVOS!$C$1:$Z$1,0))="En proceso")+--(INDEX(NORMATIVOS!$C$4:$Z$4,1,MATCH($B$3,NORMATIVOS!$C$1:$Z$1,0))="En proceso")+--(INDEX(NORMATIVOS!$C$5:$Z$5,1,MATCH($B$3,NORMATIVOS!$C$1:$Z$1,0))="En proceso")+--(INDEX(NORMATIVOS!$C$6:$Z$6,1,MATCH($B$3,NORMATIVOS!$C$1:$Z$1,0))="En proceso")+--(INDEX(NORMATIVOS!$C$7:$Z$7,1,MATCH($B$3,NORMATIVOS!$C$1:$Z$1,0))="En proceso")+--(INDEX(NORMATIVOS!$C$8:$Z$8,1,MATCH($B$3,NORMATIVOS!$C$1:$Z$1,0))="En proceso")+--(INDEX(NORMATIVOS!$C$9:$Z$9,1,MATCH($B$3,NORMATIVOS!$C$1:$Z$1,0))="En proceso")+--(INDEX(NORMATIVOS!$C$10:$Z$10,1,MATCH($B$3,NORMATIVOS!$C$1:$Z$1,0))="En proceso")+--(INDEX(NORMATIVOS!$C$11:$Z$11,1,MATCH($B$3,NORMATIVOS!$C$1:$Z$1,0))="En proceso")+--(INDEX(NORMATIVOS!$C$12:$Z$12,1,MATCH($B$3,NORMATIVOS!$C$1:$Z$1,0))="En proceso")+--(INDEX(NORMATIVOS!$C$13:$Z$13,1,MATCH($B$3,NORMATIVOS!$C$1:$Z$1,0))="En proceso")+--(INDEX(NORMATIVOS!$C$14:$Z$14,1,MATCH($B$3,NORMATIVOS!$C$1:$Z$1,0))="En proceso")+--(INDEX(NORMATIVOS!$C$15:$Z$15,1,MATCH($B$3,NORMATIVOS!$C$1:$Z$1,0))="En proceso")+--(INDEX(NORMATIVOS!$C$16:$Z$16,1,MATCH($B$3,NORMATIVOS!$C$1:$Z$1,0))="En proceso") -> 5 | G6: =--(INDEX(NORMATIVOS!$C$3:$Z$3,1,MATCH($B$3,NORMATIVOS!$C$1:$Z$1,0))="Proyección")+--(INDEX(NORMATIVOS!$C$4:$Z$4,1,MATCH($B$3,NORMATIVOS!$C$1:$Z$1,0))="Proyección")+--(INDEX(NORMATIVOS!$C$5:$Z$5,1,MATCH($B$3,NORMATIVOS!$C$1:$Z$1,0))="Proyección")+--(INDEX(NORMATIVOS!$C$6:$Z$6,1,MATCH($B$3,NORMATIVOS!$C$1:$Z$1,0))="Proyección")+--(INDEX(NORMATIVOS!$C$7:$Z$7,1,MATCH($B$3,NORMATIVOS!$C$1:$Z$1,0))="Proyección")+--(INDEX(NORMATIVOS!$C$8:$Z$8,1,MATCH($B$3,NORMATIVOS!$C$1:$Z$1,0))="Proyección")+--(INDEX(NORMATIVOS!$C$9:$Z$9,1,MATCH($B$3,NORMATIVOS!$C$1:$Z$1,0))="Proyección")+--(INDEX(NORMATIVOS!$C$10:$Z$10,1,MATCH($B$3,NORMATIVOS!$C$1:$Z$1,0))="Proyección")+--(INDEX(NORMATIVOS!$C$11:$Z$11,1,MATCH($B$3,NORMATIVOS!$C$1:$Z$1,0))="Proyección")+--(INDEX(NORMATIVOS!$C$12:$Z$12,1,MATCH($B$3,NORMATIVOS!$C$1:$Z$1,0))="Proyección")+--(INDEX(NORMATIVOS!$C$13:$Z$13,1,MATCH($B$3,NORMATIVOS!$C$1:$Z$1,0))="Proyección")+--(INDEX(NORMATIVOS!$C$14:$Z$14,1,MATCH($B$3,NORMATIVOS!$C$1:$Z$1,0))="Proyección")+--(INDEX(NORMATIVOS!$C$15:$Z$15,1,MATCH($B$3,NORMATIVOS!$C$1:$Z$1,0))="Proyección")+--(INDEX(NORMATIVOS!$C$16:$Z$16,1,MATCH($B$3,NORMATIVOS!$C$1:$Z$1,0))="Proyección") -> 0 | H6: =IFERROR(E6/(E6+F6+G6),0) -> 0.64285714
A7: Consolidados | B7: =INDEX(CONSOLIDADO!$C$4:$C$5,MATCH($B$3,CONSOLIDADO!$A$4:$A$5,0)) -> 113 | D7: ACROBATICO HACÍA DELANTE | E7: =--(INDEX(NORMATIVOS!$C$17:$Z$17,1,MATCH($B$3,NORMATIVOS!$C$1:$Z$1,0))="Consolidado")+--(INDEX(NORMATIVOS!$C$18:$Z$18,1,MATCH($B$3,NORMATIVOS!$C$1:$Z$1,0))="Consolidado")+--(INDEX(NORMATIVOS!$C$19:$Z$19,1,MATCH($B$3,NORMATIVOS!$C$1:$Z$1,0))="Consolidado")+--(INDEX(NORMATIVOS!$C$20:$Z$20,1,MATCH($B$3,NORMATIVOS!$C$1:$Z$1,0))="Consolidado")+--(INDEX(NORMATIVOS!$C$21:$Z$21,1,MATCH($B$3,NORMATIVOS!$C$1:$Z$1,0))="Consolidado")+--(INDEX(NORMATIVOS!$C$22:$Z$22,1,MATCH($B$3,NORMATIVOS!$C$1:$Z$1,0))="Consolidado")+--(INDEX(NORMATIVOS!$C$23:$Z$23,1,MATCH($B$3,NORMATIVOS!$C$1:$Z$1,0))="Consolidado")+--(INDEX(NORMATIVOS!$C$24:$Z$24,1,MATCH($B$3,NORMATIVOS!$C$1:$Z$1,0))="Consolidado")+--(INDEX(NORMATIVOS!$C$25:$Z$25,1,MATCH($B$3,NORMATIVOS!$C$1:$Z$1,0))="Consolidado")+--(INDEX(NORMATIVOS!$C$26:$Z$26,1,MATCH($B$3,NORMATIVOS!$C$1:$Z$1,0))="Consolidado")+--(INDEX(NORMATIVOS!$C$27:$Z$27,1,MATCH($B$3,NORMATIVOS!$C$1:$Z$1,0))="Consolidado") -> 8 | F7: =--(INDEX(NORMATIVOS!$C$17:$Z$17,1,MATCH($B$3,NORMATIVOS!$C$1:$Z$1,0))="En proceso")+--(INDEX(NORMATIVOS!$C$18:$Z$18,1,MATCH($B$3,NORMATIVOS!$C$1:$Z$1,0))="En proceso")+--(INDEX(NORMATIVOS!$C$19:$Z$19,1,MATCH($B$3,NORMATIVOS!$C$1:$Z$1,0))="En proceso")+--(INDEX(NORMATIVOS!$C$20:$Z$20,1,MATCH($B$3,NORMATIVOS!$C$1:$Z$1,0))="En proceso")+--(INDEX(NORMATIVOS!$C$21:$Z$21,1,MATCH($B$3,NORMATIVOS!$C$1:$Z$1,0))="En proceso")+--(INDEX(NORMATIVOS!$C$22:$Z$22,1,MATCH($B$3,NORMATIVOS!$C$1:$Z$1,0))="En proceso")+--(INDEX(NORMATIVOS!$C$23:$Z$23,1,MATCH($B$3,NORMATIVOS!$C$1:$Z$1,0))="En proceso")+--(INDEX(NORMATIVOS!$C$24:$Z$24,1,MATCH($B$3,NORMATIVOS!$C$1:$Z$1,0))="En proceso")+--(INDEX(NORMATIVOS!$C$25:$Z$25,1,MATCH($B$3,NORMATIVOS!$C$1:$Z$1,0))="En proceso")+--(INDEX(NORMATIVOS!$C$26:$Z$26,1,MATCH($B$3,NORMATIVOS!$C$1:$Z$1,0))="En proceso")+--(INDEX(NORMATIVOS!$C$27:$Z$27,1,MATCH($B$3,NORMATIVOS!$C$1:$Z$1,0))="En proceso") -> 2 | G7: =--(INDEX(NORMATIVOS!$C$17:$Z$17,1,MATCH($B$3,NORMATIVOS!$C$1:$Z$1,0))="Proyección")+--(INDEX(NORMATIVOS!$C$18:$Z$18,1,MATCH($B$3,NORMATIVOS!$C$1:$Z$1,0))="Proyección")+--(INDEX(NORMATIVOS!$C$19:$Z$19,1,MATCH($B$3,NORMATIVOS!$C$1:$Z$1,0))="Proyección")+--(INDEX(NORMATIVOS!$C$20:$Z$20,1,MATCH($B$3,NORMATIVOS!$C$1:$Z$1,0))="Proyección")+--(INDEX(NORMATIVOS!$C$21:$Z$21,1,MATCH($B$3,NORMATIVOS!$C$1:$Z$1,0))="Proyección")+--(INDEX(NORMATIVOS!$C$22:$Z$22,1,MATCH($B$3,NORMATIVOS!$C$1:$Z$1,0))="Proyección")+--(INDEX(NORMATIVOS!$C$23:$Z$23,1,MATCH($B$3,NORMATIVOS!$C$1:$Z$1,0))="Proyección")+--(INDEX(NORMATIVOS!$C$24:$Z$24,1,MATCH($B$3,NORMATIVOS!$C$1:$Z$1,0))="Proyección")+--(INDEX(NORMATIVOS!$C$25:$Z$25,1,MATCH($B$3,NORMATIVOS!$C$1:$Z$1,0))="Proyección")+--(INDEX(NORMATIVOS!$C$26:$Z$26,1,MATCH($B$3,NORMATIVOS!$C$1:$Z$1,0))="Proyección")+--(INDEX(NORMATIVOS!$C$27:$Z$27,1,MATCH($B$3,NORMATIVOS!$C$1:$Z$1,0))="Proyección") -> 1 | H7: =IFERROR(E7/(E7+F7+G7),0) -> 0.72727273
A8: En proceso | B8: =INDEX(CONSOLIDADO!$D$4:$D$5,MATCH($B$3,CONSOLIDADO!$A$4:$A$5,0)) -> 49 | D8: ACROBATICO HACÍA ATRÁS | E8: =--(INDEX(NORMATIVOS!$C$28:$Z$28,1,MATCH($B$3,NORMATIVOS!$C$1:$Z$1,0))="Consolidado")+--(INDEX(NORMATIVOS!$C$29:$Z$29,1,MATCH($B$3,NORMATIVOS!$C$1:$Z$1,0))="Consolidado")+--(INDEX(NORMATIVOS!$C$30:$Z$30,1,MATCH($B$3,NORMATIVOS!$C$1:$Z$1,0))="Consolidado")+--(INDEX(NORMATIVOS!$C$31:$Z$31,1,MATCH($B$3,NORMATIVOS!$C$1:$Z$1,0))="Consolidado")+--(INDEX(NORMATIVOS!$C$32:$Z$32,1,MATCH($B$3,NORMATIVOS!$C$1:$Z$1,0))="Consolidado")+--(INDEX(NORMATIVOS!$C$33:$Z$33,1,MATCH($B$3,NORMATIVOS!$C$1:$Z$1,0))="Consolidado")+--(INDEX(NORMATIVOS!$C$34:$Z$34,1,MATCH($B$3,NORMATIVOS!$C$1:$Z$1,0))="Consolidado")+--(INDEX(NORMATIVOS!$C$35:$Z$35,1,MATCH($B$3,NORMATIVOS!$C$1:$Z$1,0))="Consolidado")+--(INDEX(NORMATIVOS!$C$36:$Z$36,1,MATCH($B$3,NORMATIVOS!$C$1:$Z$1,0))="Consolidado")+--(INDEX(NORMATIVOS!$C$37:$Z$37,1,MATCH($B$3,NORMATIVOS!$C$1:$Z$1,0))="Consolidado") -> 5 | F8: =--(INDEX(NORMATIVOS!$C$28:$Z$28,1,MATCH($B$3,NORMATIVOS!$C$1:$Z$1,0))="En proceso")+--(INDEX(NORMATIVOS!$C$29:$Z$29,1,MATCH($B$3,NORMATIVOS!$C$1:$Z$1,0))="En proceso")+--(INDEX(NORMATIVOS!$C$30:$Z$30,1,MATCH($B$3,NORMATIVOS!$C$1:$Z$1,0))="En proceso")+--(INDEX(NORMATIVOS!$C$31:$Z$31,1,MATCH($B$3,NORMATIVOS!$C$1:$Z$1,0))="En proceso")+--(INDEX(NORMATIVOS!$C$32:$Z$32,1,MATCH($B$3,NORMATIVOS!$C$1:$Z$1,0))="En proceso")+--(INDEX(NORMATIVOS!$C$33:$Z$33,1,MATCH($B$3,NORMATIVOS!$C$1:$Z$1,0))="En proceso")+--(INDEX(NORMATIVOS!$C$34:$Z$34,1,MATCH($B$3,NORMATIVOS!$C$1:$Z$1,0))="En proceso")+--(INDEX(NORMATIVOS!$C$35:$Z$35,1,MATCH($B$3,NORMATIVOS!$C$1:$Z$1,0))="En proceso")+--(INDEX(NORMATIVOS!$C$36:$Z$36,1,MATCH($B$3,NORMATIVOS!$C$1:$Z$1,0))="En proceso")+--(INDEX(NORMATIVOS!$C$37:$Z$37,1,MATCH($B$3,NORMATIVOS!$C$1:$Z$1,0))="En proceso") -> 4 | G8: =--(INDEX(NORMATIVOS!$C$28:$Z$28,1,MATCH($B$3,NORMATIVOS!$C$1:$Z$1,0))="Proyección")+--(INDEX(NORMATIVOS!$C$29:$Z$29,1,MATCH($B$3,NORMATIVOS!$C$1:$Z$1,0))="Proyección")+--(INDEX(NORMATIVOS!$C$30:$Z$30,1,MATCH($B$3,NORMATIVOS!$C$1:$Z$1,0))="Proyección")+--(INDEX(NORMATIVOS!$C$31:$Z$31,1,MATCH($B$3,NORMATIVOS!$C$1:$Z$1,0))="Proyección")+--(INDEX(NORMATIVOS!$C$32:$Z$32,1,MATCH($B$3,NORMATIVOS!$C$1:$Z$1,0))="Proyección")+--(INDEX(NORMATIVOS!$C$33:$Z$33,1,MATCH($B$3,NORMATIVOS!$C$1:$Z$1,0))="Proyección")+--(INDEX(NORMATIVOS!$C$34:$Z$34,1,MATCH($B$3,NORMATIVOS!$C$1:$Z$1,0))="Proyección")+--(INDEX(NORMATIVOS!$C$35:$Z$35,1,MATCH($B$3,NORMATIVOS!$C$1:$Z$1,0))="Proyección")+--(INDEX(NORMATIVOS!$C$36:$Z$36,1,MATCH($B$3,NORMATIVOS!$C$1:$Z$1,0))="Proyección")+--(INDEX(NORMATIVOS!$C$37:$Z$37,1,MATCH($B$3,NORMATIVOS!$C$1:$Z$1,0))="Proyección") -> 1 | H8: =IFERROR(E8/(E8+F8+G8),0) -> 0.5
A9: Proyección | B9: =INDEX(CONSOLIDADO!$E$4:$E$5,MATCH($B$3,CONSOLIDADO!$A$4:$A$5,0)) -> 100 | D9: ACROBATICO CON GIRO | E9: =--(INDEX(NORMATIVOS!$C$38:$Z$38,1,MATCH($B$3,NORMATIVOS!$C$1:$Z$1,0))="Consolidado")+--(INDEX(NORMATIVOS!$C$39:$Z$39,1,MATCH($B$3,NORMATIVOS!$C$1:$Z$1,0))="Consolidado")+--(INDEX(NORMATIVOS!$C$40:$Z$40,1,MATCH($B$3,NORMATIVOS!$C$1:$Z$1,0))="Consolidado")+--(INDEX(NORMATIVOS!$C$41:$Z$41,1,MATCH($B$3,NORMATIVOS!$C$1:$Z$1,0))="Consolidado")+--(INDEX(NORMATIVOS!$C$42:$Z$42,1,MATCH($B$3,NORMATIVOS!$C$1:$Z$1,0))="Consolidado")+--(INDEX(NORMATIVOS!$C$43:$Z$43,1,MATCH($B$3,NORMATIVOS!$C$1:$Z$1,0))="Consolidado")+--(INDEX(NORMATIVOS!$C$44:$Z$44,1,MATCH($B$3,NORMATIVOS!$C$1:$Z$1,0))="Consolidado")+--(INDEX(NORMATIVOS!$C$45:$Z$45,1,MATCH($B$3,NORMATIVOS!$C$1:$Z$1,0))="Consolidado")+--(INDEX(NORMATIVOS!$C$46:$Z$46,1,MATCH($B$3,NORMATIVOS!$C$1:$Z$1,0))="Consolidado") -> 0 | F9: =--(INDEX(NORMATIVOS!$C$38:$Z$38,1,MATCH($B$3,NORMATIVOS!$C$1:$Z$1,0))="En proceso")+--(INDEX(NORMATIVOS!$C$39:$Z$39,1,MATCH($B$3,NORMATIVOS!$C$1:$Z$1,0))="En proceso")+--(INDEX(NORMATIVOS!$C$40:$Z$40,1,MATCH($B$3,NORMATIVOS!$C$1:$Z$1,0))="En proceso")+--(INDEX(NORMATIVOS!$C$41:$Z$41,1,MATCH($B$3,NORMATIVOS!$C$1:$Z$1,0))="En proceso")+--(INDEX(NORMATIVOS!$C$42:$Z$42,1,MATCH($B$3,NORMATIVOS!$C$1:$Z$1,0))="En proceso")+--(INDEX(NORMATIVOS!$C$43:$Z$43,1,MATCH($B$3,NORMATIVOS!$C$1:$Z$1,0))="En proceso")+--(INDEX(NORMATIVOS!$C$44:$Z$44,1,MATCH($B$3,NORMATIVOS!$C$1:$Z$1,0))="En proceso")+--(INDEX(NORMATIVOS!$C$45:$Z$45,1,MATCH($B$3,NORMATIVOS!$C$1:$Z$1,0))="En proceso")+--(INDEX(NORMATIVOS!$C$46:$Z$46,1,MATCH($B$3,NORMATIVOS!$C$1:$Z$1,0))="En proceso") -> 7 | G9: =--(INDEX(NORMATIVOS!$C$38:$Z$38,1,MATCH($B$3,NORMATIVOS!$C$1:$Z$1,0))="Proyección")+--(INDEX(NORMATIVOS!$C$39:$Z$39,1,MATCH($B$3,NORMATIVOS!$C$1:$Z$1,0))="Proyección")+--(INDEX(NORMATIVOS!$C$40:$Z$40,1,MATCH($B$3,NORMATIVOS!$C$1:$Z$1,0))="Proyección")+--(INDEX(NORMATIVOS!$C$41:$Z$41,1,MATCH($B$3,NORMATIVOS!$C$1:$Z$1,0))="Proyección")+--(INDEX(NORMATIVOS!$C$42:$Z$42,1,MATCH($B$3,NORMATIVOS!$C$1:$Z$1,0))="Proyección")+--(INDEX(NORMATIVOS!$C$43:$Z$43,1,MATCH($B$3,NORMATIVOS!$C$1:$Z$1,0))="Proyección")+--(INDEX(NORMATIVOS!$C$44:$Z$44,1,MATCH($B$3,NORMATIVOS!$C$1:$Z$1,0))="Proyección")+--(INDEX(NORMATIVOS!$C$45:$Z$45,1,MATCH($B$3,NORMATIVOS!$C$1:$Z$1,0))="Proyección")+--(INDEX(NORMATIVOS!$C$46:$Z$46,1,MATCH($B$3,NORMATIVOS!$C$1:$Z$1,0))="Proyección") -> 0 | H9: =IFERROR(E9/(E9+F9+G9),0) -> 0
A10: N/A | B10: =INDEX(CONSOLIDADO!$F$4:$F$5,MATCH($B$3,CONSOLIDADO!$A$4:$A$5,0)) -> 2 | D10: HONGO | E10: =--(INDEX(NORMATIVOS!$C$49:$Z$49,1,MATCH($B$3,NORMATIVOS!$C$1:$Z$1,0))="Consolidado")+--(INDEX(NORMATIVOS!$C$50:$Z$50,1,MATCH($B$3,NORMATIVOS!$C$1:$Z$1,0))="Consolidado")+--(INDEX(NORMATIVOS!$C$51:$Z$51,1,MATCH($B$3,NORMATIVOS!$C$1:$Z$1,0))="Consolidado")+--(INDEX(NORMATIVOS!$C$52:$Z$52,1,MATCH($B$3,NORMATIVOS!$C$1:$Z$1,0))="Consolidado")+--(INDEX(NORMATIVOS!$C$53:$Z$53,1,MATCH($B$3,NORMATIVOS!$C$1:$Z$1,0))="Consolidado")+--(INDEX(NORMATIVOS!$C$54:$Z$54,1,MATCH($B$3,NORMATIVOS!$C$1:$Z$1,0))="Consolidado")+--(INDEX(NORMATIVOS!$C$55:$Z$55,1,MATCH($B$3,NORMATIVOS!$C$1:$Z$1,0))="Consolidado")+--(INDEX(NORMATIVOS!$C$56:$Z$56,1,MATCH($B$3,NORMATIVOS!$C$1:$Z$1,0))="Consolidado")+--(INDEX(NORMATIVOS!$C$57:$Z$57,1,MATCH($B$3,NORMATIVOS!$C$1:$Z$1,0))="Consolidado")+--(INDEX(NORMATIVOS!$C$58:$Z$58,1,MATCH($B$3,NORMATIVOS!$C$1:$Z$1,0))="Consolidado")+--(INDEX(NORMATIVOS!$C$59:$Z$59,1,MATCH($B$3,NORMATIVOS!$C$1:$Z$1,0))="Consolidado")+--(INDEX(NORMATIVOS!$C$60:$Z$60,1,MATCH($B$3,NORMATIVOS!$C$1:$Z$1,0))="Consolidado")+--(INDEX(NORMATIVOS!$C$61:$Z$61,1,MATCH($B$3,NORMATIVOS!$C$1:$Z$1,0))="Consolidado")+--(INDEX(NORMATIVOS!$C$62:$Z$62,1,MATCH($B$3,NORMATIVOS!$C$1:$Z$1,0))="Consolidado")+--(INDEX(NORMATIVOS!$C$63:$Z$63,1,MATCH($B$3,NORMATIVOS!$C$1:$Z$1,0))="Consolidado")+--(INDEX(NORMATIVOS!$C$64:$Z$64,1,MATCH($B$3,NORMATIVOS!$C$1:$Z$1,0))="Consolidado") -> 13 | F10: =--(INDEX(NORMATIVOS!$C$49:$Z$49,1,MATCH($B$3,NORMATIVOS!$C$1:$Z$1,0))="En proceso")+--(INDEX(NORMATIVOS!$C$50:$Z$50,1,MATCH($B$3,NORMATIVOS!$C$1:$Z$1,0))="En proceso")+--(INDEX(NORMATIVOS!$C$51:$Z$51,1,MATCH($B$3,NORMATIVOS!$C$1:$Z$1,0))="En proceso")+--(INDEX(NORMATIVOS!$C$52:$Z$52,1,MATCH($B$3,NORMATIVOS!$C$1:$Z$1,0))="En proceso")+--(INDEX(NORMATIVOS!$C$53:$Z$53,1,MATCH($B$3,NORMATIVOS!$C$1:$Z$1,0))="En proceso")+--(INDEX(NORMATIVOS!$C$54:$Z$54,1,MATCH($B$3,NORMATIVOS!$C$1:$Z$1,0))="En proceso")+--(INDEX(NORMATIVOS!$C$55:$Z$55,1,MATCH($B$3,NORMATIVOS!$C$1:$Z$1,0))="En proceso")+--(INDEX(NORMATIVOS!$C$56:$Z$56,1,MATCH($B$3,NORMATIVOS!$C$1:$Z$1,0))="En proceso")+--(INDEX(NORMATIVOS!$C$57:$Z$57,1,MATCH($B$3,NORMATIVOS!$C$1:$Z$1,0))="En proceso")+--(INDEX(NORMATIVOS!$C$58:$Z$58,1,MATCH($B$3,NORMATIVOS!$C$1:$Z$1,0))="En proceso")+--(INDEX(NORMATIVOS!$C$59:$Z$59,1,MATCH($B$3,NORMATIVOS!$C$1:$Z$1,0))="En proceso")+--(INDEX(NORMATIVOS!$C$60:$Z$60,1,MATCH($B$3,NORMATIVOS!$C$1:$Z$1,0))="En proceso")+--(INDEX(NORMATIVOS!$C$61:$Z$61,1,MATCH($B$3,NORMATIVOS!$C$1:$Z$1,0))="En proceso")+--(INDEX(NORMATIVOS!$C$62:$Z$62,1,MATCH($B$3,NORMATIVOS!$C$1:$Z$1,0))="En proceso")+--(INDEX(NORMATIVOS!$C$63:$Z$63,1,MATCH($B$3,NORMATIVOS!$C$1:$Z$1,0))="En proceso")+--(INDEX(NORMATIVOS!$C$64:$Z$64,1,MATCH($B$3,NORMATIVOS!$C$1:$Z$1,0))="En proceso") -> 1 | G10: =--(INDEX(NORMATIVOS!$C$49:$Z$49,1,MATCH($B$3,NORMATIVOS!$C$1:$Z$1,0))="Proyección")+--(INDEX(NORMATIVOS!$C$50:$Z$50,1,MATCH($B$3,NORMATIVOS!$C$1:$Z$1,0))="Proyección")+--(INDEX(NORMATIVOS!$C$51:$Z$51,1,MATCH($B$3,NORMATIVOS!$C$1:$Z$1,0))="Proyección")+--(INDEX(NORMATIVOS!$C$52:$Z$52,1,MATCH($B$3,NORMATIVOS!$C$1:$Z$1,0))="Proyección")+--(INDEX(NORMATIVOS!$C$53:$Z$53,1,MATCH($B$3,NORMATIVOS!$C$1:$Z$1,0))="Proyección")+--(INDEX(NORMATIVOS!$C$54:$Z$54,1,MATCH($B$3,NORMATIVOS!$C$1:$Z$1,0))="Proyección")+--(INDEX(NORMATIVOS!$C$55:$Z$55,1,MATCH($B$3,NORMATIVOS!$C$1:$Z$1,0))="Proyección")+--(INDEX(NORMATIVOS!$C$56:$Z$56,1,MATCH($B$3,NORMATIVOS!$C$1:$Z$1,0))="Proyección")+--(INDEX(NORMATIVOS!$C$57:$Z$57,1,MATCH($B$3,NORMATIVOS!$C$1:$Z$1,0))="Proyección")+--(INDEX(NORMATIVOS!$C$58:$Z$58,1,MATCH($B$3,NORMATIVOS!$C$1:$Z$1,0))="Proyección")+--(INDEX(NORMATIVOS!$C$59:$Z$59,1,MATCH($B$3,NORMATIVOS!$C$1:$Z$1,0))="Proyección")+--(INDEX(NORMATIVOS!$C$60:$Z$60,1,MATCH($B$3,NORMATIVOS!$C$1:$Z$1,0))="Proyección")+--(INDEX(NORMATIVOS!$C$61:$Z$61,1,MATCH($B$3,NORMATIVOS!$C$1:$Z$1,0))="Proyección")+--(INDEX(NORMATIVOS!$C$62:$Z$62,1,MATCH($B$3,NORMATIVOS!$C$1:$Z$1,0))="Proyección")+--(INDEX(NORMATIVOS!$C$63:$Z$63,1,MATCH($B$3,NORMATIVOS!$C$1:$Z$1,0))="Proyección")+--(INDEX(NORMATIVOS!$C$64:$Z$64,1,MATCH($B$3,NORMATIVOS!$C$1:$Z$1,0))="Proyección") -> 2 | H10: =IFERROR(E10/(E10+F10+G10),0) -> 0.8125
A11: % dominio | B11: =INDEX(CONSOLIDADO!$G$4:$G$5,MATCH($B$3,CONSOLIDADO!$A$4:$A$5,0)) -> 0.43129771 | D11: CABALLO SIN ARZON | E11: =--(INDEX(NORMATIVOS!$C$65:$Z$65,1,MATCH($B$3,NORMATIVOS!$C$1:$Z$1,0))="Consolidado")+--(INDEX(NORMATIVOS!$C$66:$Z$66,1,MATCH($B$3,NORMATIVOS!$C$1:$Z$1,0))="Consolidado")+--(INDEX(NORMATIVOS!$C$67:$Z$67,1,MATCH($B$3,NORMATIVOS!$C$1:$Z$1,0))="Consolidado")+--(INDEX(NORMATIVOS!$C$68:$Z$68,1,MATCH($B$3,NORMATIVOS!$C$1:$Z$1,0))="Consolidado")+--(INDEX(NORMATIVOS!$C$69:$Z$69,1,MATCH($B$3,NORMATIVOS!$C$1:$Z$1,0))="Consolidado")+--(INDEX(NORMATIVOS!$C$70:$Z$70,1,MATCH($B$3,NORMATIVOS!$C$1:$Z$1,0))="Consolidado")+--(INDEX(NORMATIVOS!$C$71:$Z$71,1,MATCH($B$3,NORMATIVOS!$C$1:$Z$1,0))="Consolidado")+--(INDEX(NORMATIVOS!$C$72:$Z$72,1,MATCH($B$3,NORMATIVOS!$C$1:$Z$1,0))="Consolidado")+--(INDEX(NORMATIVOS!$C$73:$Z$73,1,MATCH($B$3,NORMATIVOS!$C$1:$Z$1,0))="Consolidado")+--(INDEX(NORMATIVOS!$C$74:$Z$74,1,MATCH($B$3,NORMATIVOS!$C$1:$Z$1,0))="Consolidado")+--(INDEX(NORMATIVOS!$C$75:$Z$75,1,MATCH($B$3,NORMATIVOS!$C$1:$Z$1,0))="Consolidado")+--(INDEX(NORMATIVOS!$C$76:$Z$76,1,MATCH($B$3,NORMATIVOS!$C$1:$Z$1,0))="Consolidado")+--(INDEX(NORMATIVOS!$C$77:$Z$77,1,MATCH($B$3,NORMATIVOS!$C$1:$Z$1,0))="Consolidado")+--(INDEX(NORMATIVOS!$C$78:$Z$78,1,MATCH($B$3,NORMATIVOS!$C$1:$Z$1,0))="Consolidado") -> 7 | F11: =--(INDEX(NORMATIVOS!$C$65:$Z$65,1,MATCH($B$3,NORMATIVOS!$C$1:$Z$1,0))="En proceso")+--(INDEX(NORMATIVOS!$C$66:$Z$66,1,MATCH($B$3,NORMATIVOS!$C$1:$Z$1,0))="En proceso")+--(INDEX(NORMATIVOS!$C$67:$Z$67,1,MATCH($B$3,NORMATIVOS!$C$1:$Z$1,0))="En proceso")+--(INDEX(NORMATIVOS!$C$68:$Z$68,1,MATCH($B$3,NORMATIVOS!$C$1:$Z$1,0))="En proceso")+--(INDEX(NORMATIVOS!$C$69:$Z$69,1,MATCH($B$3,NORMATIVOS!$C$1:$Z$1,0))="En proceso")+--(INDEX(NORMATIVOS!$C$70:$Z$70,1,MATCH($B$3,NORMATIVOS!$C$1:$Z$1,0))="En proceso")+--(INDEX(NORMATIVOS!$C$71:$Z$71,1,MATCH($B$3,NORMATIVOS!$C$1:$Z$1,0))="En proceso")+--(INDEX(NORMATIVOS!$C$72:$Z$72,1,MATCH($B$3,NORMATIVOS!$C$1:$Z$1,0))="En proceso")+--(INDEX(NORMATIVOS!$C$73:$Z$73,1,MATCH($B$3,NORMATIVOS!$C$1:$Z$1,0))="En proceso")+--(INDEX(NORMATIVOS!$C$74:$Z$74,1,MATCH($B$3,NORMATIVOS!$C$1:$Z$1,0))="En proceso")+--(INDEX(NORMATIVOS!$C$75:$Z$75,1,MATCH($B$3,NORMATIVOS!$C$1:$Z$1,0))="En proceso")+--(INDEX(NORMATIVOS!$C$76:$Z$76,1,MATCH($B$3,NORMATIVOS!$C$1:$Z$1,0))="En proceso")+--(INDEX(NORMATIVOS!$C$77:$Z$77,1,MATCH($B$3,NORMATIVOS!$C$1:$Z$1,0))="En proceso")+--(INDEX(NORMATIVOS!$C$78:$Z$78,1,MATCH($B$3,NORMATIVOS!$C$1:$Z$1,0))="En proceso") -> 4 | G11: =--(INDEX(NORMATIVOS!$C$65:$Z$65,1,MATCH($B$3,NORMATIVOS!$C$1:$Z$1,0))="Proyección")+--(INDEX(NORMATIVOS!$C$66:$Z$66,1,MATCH($B$3,NORMATIVOS!$C$1:$Z$1,0))="Proyección")+--(INDEX(NORMATIVOS!$C$67:$Z$67,1,MATCH($B$3,NORMATIVOS!$C$1:$Z$1,0))="Proyección")+--(INDEX(NORMATIVOS!$C$68:$Z$68,1,MATCH($B$3,NORMATIVOS!$C$1:$Z$1,0))="Proyección")+--(INDEX(NORMATIVOS!$C$69:$Z$69,1,MATCH($B$3,NORMATIVOS!$C$1:$Z$1,0))="Proyección")+--(INDEX(NORMATIVOS!$C$70:$Z$70,1,MATCH($B$3,NORMATIVOS!$C$1:$Z$1,0))="Proyección")+--(INDEX(NORMATIVOS!$C$71:$Z$71,1,MATCH($B$3,NORMATIVOS!$C$1:$Z$1,0))="Proyección")+--(INDEX(NORMATIVOS!$C$72:$Z$72,1,MATCH($B$3,NORMATIVOS!$C$1:$Z$1,0))="Proyección")+--(INDEX(NORMATIVOS!$C$73:$Z$73,1,MATCH($B$3,NORMATIVOS!$C$1:$Z$1,0))="Proyección")+--(INDEX(NORMATIVOS!$C$74:$Z$74,1,MATCH($B$3,NORMATIVOS!$C$1:$Z$1,0))="Proyección")+--(INDEX(NORMATIVOS!$C$75:$Z$75,1,MATCH($B$3,NORMATIVOS!$C$1:$Z$1,0))="Proyección")+--(INDEX(NORMATIVOS!$C$76:$Z$76,1,MATCH($B$3,NORMATIVOS!$C$1:$Z$1,0))="Proyección")+--(INDEX(NORMATIVOS!$C$77:$Z$77,1,MATCH($B$3,NORMATIVOS!$C$1:$Z$1,0))="Proyección")+--(INDEX(NORMATIVOS!$C$78:$Z$78,1,MATCH($B$3,NORMATIVOS!$C$1:$Z$1,0))="Proyección") -> 3 | H11: =IFERROR(E11/(E11+F11+G11),0) -> 0.5
D12: CABALLO CON ARZONES | E12: =--(INDEX(NORMATIVOS!$C$79:$Z$79,1,MATCH($B$3,NORMATIVOS!$C$1:$Z$1,0))="Consolidado")+--(INDEX(NORMATIVOS!$C$80:$Z$80,1,MATCH($B$3,NORMATIVOS!$C$1:$Z$1,0))="Consolidado")+--(INDEX(NORMATIVOS!$C$81:$Z$81,1,MATCH($B$3,NORMATIVOS!$C$1:$Z$1,0))="Consolidado")+--(INDEX(NORMATIVOS!$C$82:$Z$82,1,MATCH($B$3,NORMATIVOS!$C$1:$Z$1,0))="Consolidado")+--(INDEX(NORMATIVOS!$C$83:$Z$83,1,MATCH($B$3,NORMATIVOS!$C$1:$Z$1,0))="Consolidado")+--(INDEX(NORMATIVOS!$C$84:$Z$84,1,MATCH($B$3,NORMATIVOS!$C$1:$Z$1,0))="Consolidado")+--(INDEX(NORMATIVOS!$C$85:$Z$85,1,MATCH($B$3,NORMATIVOS!$C$1:$Z$1,0))="Consolidado")+--(INDEX(NORMATIVOS!$C$86:$Z$86,1,MATCH($B$3,NORMATIVOS!$C$1:$Z$1,0))="Consolidado")+--(INDEX(NORMATIVOS!$C$87:$Z$87,1,MATCH($B$3,NORMATIVOS!$C$1:$Z$1,0))="Consolidado")+--(INDEX(NORMATIVOS!$C$88:$Z$88,1,MATCH($B$3,NORMATIVOS!$C$1:$Z$1,0))="Consolidado")+--(INDEX(NORMATIVOS!$C$89:$Z$89,1,MATCH($B$3,NORMATIVOS!$C$1:$Z$1,0))="Consolidado")+--(INDEX(NORMATIVOS!$C$90:$Z$90,1,MATCH($B$3,NORMATIVOS!$C$1:$Z$1,0))="Consolidado")+--(INDEX(NORMATIVOS!$C$91:$Z$91,1,MATCH($B$3,NORMATIVOS!$C$1:$Z$1,0))="Consolidado")+--(INDEX(NORMATIVOS!$C$92:$Z$92,1,MATCH($B$3,NORMATIVOS!$C$1:$Z$1,0))="Consolidado")+--(INDEX(NORMATIVOS!$C$93:$Z$93,1,MATCH($B$3,NORMATIVOS!$C$1:$Z$1,0))="Consolidado")+--(INDEX(NORMATIVOS!$C$94:$Z$94,1,MATCH($B$3,NORMATIVOS!$C$1:$Z$1,0))="Consolidado")+--(INDEX(NORMATIVOS!$C$95:$Z$95,1,MATCH($B$3,NORMATIVOS!$C$1:$Z$1,0))="Consolidado")+--(INDEX(NORMATIVOS!$C$96:$Z$96,1,MATCH($B$3,NORMATIVOS!$C$1:$Z$1,0))="Consolidado")+--(INDEX(NORMATIVOS!$C$97:$Z$97,1,MATCH($B$3,NORMATIVOS!$C$1:$Z$1,0))="Consolidado")+--(INDEX(NORMATIVOS!$C$98:$Z$98,1,MATCH($B$3,NORMATIVOS!$C$1:$Z$1,0))="Consolidado")+--(INDEX(NORMATIVOS!$C$99:$Z$99,1,MATCH($B$3,NORMATIVOS!$C$1:$Z$1,0))="Consolidado")+--(INDEX(NORMATIVOS!$C$100:$Z$100,1,MATCH($B$3,NORMATIVOS!$C$1:$Z$1,0))="Consolidado")+--(INDEX(NORMATIVOS!$C$101:$Z$101,1,MATCH($B$3,NORMATIVOS!$C$1:$Z$1,0))="Consolidado")+--(INDEX(NORMATIVOS!$C$102:$Z$102,1,MATCH($B$3,NORMATIVOS!$C$1:$Z$1,0))="Consolidado")+--(INDEX(NORMATIVOS!$C$103:$Z$103,1,MATCH($B$3,NORMATIVOS!$C$1:$Z$1,0))="Consolidado")+--(INDEX(NORMATIVOS!$C$104:$Z$104,1,MATCH($B$3,NORMATIVOS!$C$1:$Z$1,0))="Consolidado") -> 3 | F12: =--(INDEX(NORMATIVOS!$C$79:$Z$79,1,MATCH($B$3,NORMATIVOS!$C$1:$Z$1,0))="En proceso")+--(INDEX(NORMATIVOS!$C$80:$Z$80,1,MATCH($B$3,NORMATIVOS!$C$1:$Z$1,0))="En proceso")+--(INDEX(NORMATIVOS!$C$81:$Z$81,1,MATCH($B$3,NORMATIVOS!$C$1:$Z$1,0))="En proceso")+--(INDEX(NORMATIVOS!$C$82:$Z$82,1,MATCH($B$3,NORMATIVOS!$C$1:$Z$1,0))="En proceso")+--(INDEX(NORMATIVOS!$C$83:$Z$83,1,MATCH($B$3,NORMATIVOS!$C$1:$Z$1,0))="En proceso")+--(INDEX(NORMATIVOS!$C$84:$Z$84,1,MATCH($B$3,NORMATIVOS!$C$1:$Z$1,0))="En proceso")+--(INDEX(NORMATIVOS!$C$85:$Z$85,1,MATCH($B$3,NORMATIVOS!$C$1:$Z$1,0))="En proceso")+--(INDEX(NORMATIVOS!$C$86:$Z$86,1,MATCH($B$3,NORMATIVOS!$C$1:$Z$1,0))="En proceso")+--(INDEX(NORMATIVOS!$C$87:$Z$87,1,MATCH($B$3,NORMATIVOS!$C$1:$Z$1,0))="En proceso")+--(INDEX(NORMATIVOS!$C$88:$Z$88,1,MATCH($B$3,NORMATIVOS!$C$1:$Z$1,0))="En proceso")+--(INDEX(NORMATIVOS!$C$89:$Z$89,1,MATCH($B$3,NORMATIVOS!$C$1:$Z$1,0))="En proceso")+--(INDEX(NORMATIVOS!$C$90:$Z$90,1,MATCH($B$3,NORMATIVOS!$C$1:$Z$1,0))="En proceso")+--(INDEX(NORMATIVOS!$C$91:$Z$91,1,MATCH($B$3,NORMATIVOS!$C$1:$Z$1,0))="En proceso")+--(INDEX(NORMATIVOS!$C$92:$Z$92,1,MATCH($B$3,NORMATIVOS!$C$1:$Z$1,0))="En proceso")+--(INDEX(NORMATIVOS!$C$93:$Z$93,1,MATCH($B$3,NORMATIVOS!$C$1:$Z$1,0))="En proceso")+--(INDEX(NORMATIVOS!$C$94:$Z$94,1,MATCH($B$3,NORMATIVOS!$C$1:$Z$1,0))="En proceso")+--(INDEX(NORMATIVOS!$C$95:$Z$95,1,MATCH($B$3,NORMATIVOS!$C$1:$Z$1,0))="En proceso")+--(INDEX(NORMATIVOS!$C$96:$Z$96,1,MATCH($B$3,NORMATIVOS!$C$1:$Z$1,0))="En proceso")+--(INDEX(NORMATIVOS!$C$97:$Z$97,1,MATCH($B$3,NORMATIVOS!$C$1:$Z$1,0))="En proceso")+--(INDEX(NORMATIVOS!$C$98:$Z$98,1,MATCH($B$3,NORMATIVOS!$C$1:$Z$1,0))="En proceso")+--(INDEX(NORMATIVOS!$C$99:$Z$99,1,MATCH($B$3,NORMATIVOS!$C$1:$Z$1,0))="En proceso")+--(INDEX(NORMATIVOS!$C$100:$Z$100,1,MATCH($B$3,NORMATIVOS!$C$1:$Z$1,0))="En proceso")+--(INDEX(NORMATIVOS!$C$101:$Z$101,1,MATCH($B$3,NORMATIVOS!$C$1:$Z$1,0))="En proceso")+--(INDEX(NORMATIVOS!$C$102:$Z$102,1,MATCH($B$3,NORMATIVOS!$C$1:$Z$1,0))="En proceso")+--(INDEX(NORMATIVOS!$C$103:$Z$103,1,MATCH($B$3,NORMATIVOS!$C$1:$Z$1,0))="En proceso")+--(INDEX(NORMATIVOS!$C$104:$Z$104,1,MATCH($B$3,NORMATIVOS!$C$1:$Z$1,0))="En proceso") -> 2 | G12: =--(INDEX(NORMATIVOS!$C$79:$Z$79,1,MATCH($B$3,NORMATIVOS!$C$1:$Z$1,0))="Proyección")+--(INDEX(NORMATIVOS!$C$80:$Z$80,1,MATCH($B$3,NORMATIVOS!$C$1:$Z$1,0))="Proyección")+--(INDEX(NORMATIVOS!$C$81:$Z$81,1,MATCH($B$3,NORMATIVOS!$C$1:$Z$1,0))="Proyección")+--(INDEX(NORMATIVOS!$C$82:$Z$82,1,MATCH($B$3,NORMATIVOS!$C$1:$Z$1,0))="Proyección")+--(INDEX(NORMATIVOS!$C$83:$Z$83,1,MATCH($B$3,NORMATIVOS!$C$1:$Z$1,0))="Proyección")+--(INDEX(NORMATIVOS!$C$84:$Z$84,1,MATCH($B$3,NORMATIVOS!$C$1:$Z$1,0))="Proyección")+--(INDEX(NORMATIVOS!$C$85:$Z$85,1,MATCH($B$3,NORMATIVOS!$C$1:$Z$1,0))="Proyección")+--(INDEX(NORMATIVOS!$C$86:$Z$86,1,MATCH($B$3,NORMATIVOS!$C$1:$Z$1,0))="Proyección")+--(INDEX(NORMATIVOS!$C$87:$Z$87,1,MATCH($B$3,NORMATIVOS!$C$1:$Z$1,0))="Proyección")+--(INDEX(NORMATIVOS!$C$88:$Z$88,1,MATCH($B$3,NORMATIVOS!$C$1:$Z$1,0))="Proyección")+--(INDEX(NORMATIVOS!$C$89:$Z$89,1,MATCH($B$3,NORMATIVOS!$C$1:$Z$1,0))="Proyección")+--(INDEX(NORMATIVOS!$C$90:$Z$90,1,MATCH($B$3,NORMATIVOS!$C$1:$Z$1,0))="Proyección")+--(INDEX(NORMATIVOS!$C$91:$Z$91,1,MATCH($B$3,NORMATIVOS!$C$1:$Z$1,0))="Proyección")+--(INDEX(NORMATIVOS!$C$92:$Z$92,1,MATCH($B$3,NORMATIVOS!$C$1:$Z$1,0))="Proyección")+--(INDEX(NORMATIVOS!$C$93:$Z$93,1,MATCH($B$3,NORMATIVOS!$C$1:$Z$1,0))="Proyección")+--(INDEX(NORMATIVOS!$C$94:$Z$94,1,MATCH($B$3,NORMATIVOS!$C$1:$Z$1,0))="Proyección")+--(INDEX(NORMATIVOS!$C$95:$Z$95,1,MATCH($B$3,NORMATIVOS!$C$1:$Z$1,0))="Proyección")+--(INDEX(NORMATIVOS!$C$96:$Z$96,1,MATCH($B$3,NORMATIVOS!$C$1:$Z$1,0))="Proyección")+--(INDEX(NORMATIVOS!$C$97:$Z$97,1,MATCH($B$3,NORMATIVOS!$C$1:$Z$1,0))="Proyección")+--(INDEX(NORMATIVOS!$C$98:$Z$98,1,MATCH($B$3,NORMATIVOS!$C$1:$Z$1,0))="Proyección")+--(INDEX(NORMATIVOS!$C$99:$Z$99,1,MATCH($B$3,NORMATIVOS!$C$1:$Z$1,0))="Proyección")+--(INDEX(NORMATIVOS!$C$100:$Z$100,1,MATCH($B$3,NORMATIVOS!$C$1:$Z$1,0))="Proyección")+--(INDEX(NORMATIVOS!$C$101:$Z$101,1,MATCH($B$3,NORMATIVOS!$C$1:$Z$1,0))="Proyección")+--(INDEX(NORMATIVOS!$C$102:$Z$102,1,MATCH($B$3,NORMATIVOS!$C$1:$Z$1,0))="Proyección")+--(INDEX(NORMATIVOS!$C$103:$Z$103,1,MATCH($B$3,NORMATIVOS!$C$1:$Z$1,0))="Proyección")+--(INDEX(NORMATIVOS!$C$104:$Z$104,1,MATCH($B$3,NORMATIVOS!$C$1:$Z$1,0))="Proyección") -> 21 | H12: =IFERROR(E12/(E12+F12+G12),0) -> 0.11538462
D13: ELEMENTOS DE FUERZA | E13: =--(INDEX(NORMATIVOS!$C$107:$Z$107,1,MATCH($B$3,NORMATIVOS!$C$1:$Z$1,0))="Consolidado")+--(INDEX(NORMATIVOS!$C$108:$Z$108,1,MATCH($B$3,NORMATIVOS!$C$1:$Z$1,0))="Consolidado")+--(INDEX(NORMATIVOS!$C$109:$Z$109,1,MATCH($B$3,NORMATIVOS!$C$1:$Z$1,0))="Consolidado")+--(INDEX(NORMATIVOS!$C$110:$Z$110,1,MATCH($B$3,NORMATIVOS!$C$1:$Z$1,0))="Consolidado")+--(INDEX(NORMATIVOS!$C$111:$Z$111,1,MATCH($B$3,NORMATIVOS!$C$1:$Z$1,0))="Consolidado")+--(INDEX(NORMATIVOS!$C$112:$Z$112,1,MATCH($B$3,NORMATIVOS!$C$1:$Z$1,0))="Consolidado")+--(INDEX(NORMATIVOS!$C$113:$Z$113,1,MATCH($B$3,NORMATIVOS!$C$1:$Z$1,0))="Consolidado")+--(INDEX(NORMATIVOS!$C$114:$Z$114,1,MATCH($B$3,NORMATIVOS!$C$1:$Z$1,0))="Consolidado")+--(INDEX(NORMATIVOS!$C$115:$Z$115,1,MATCH($B$3,NORMATIVOS!$C$1:$Z$1,0))="Consolidado")+--(INDEX(NORMATIVOS!$C$116:$Z$116,1,MATCH($B$3,NORMATIVOS!$C$1:$Z$1,0))="Consolidado")+--(INDEX(NORMATIVOS!$C$117:$Z$117,1,MATCH($B$3,NORMATIVOS!$C$1:$Z$1,0))="Consolidado")+--(INDEX(NORMATIVOS!$C$118:$Z$118,1,MATCH($B$3,NORMATIVOS!$C$1:$Z$1,0))="Consolidado")+--(INDEX(NORMATIVOS!$C$119:$Z$119,1,MATCH($B$3,NORMATIVOS!$C$1:$Z$1,0))="Consolidado")+--(INDEX(NORMATIVOS!$C$120:$Z$120,1,MATCH($B$3,NORMATIVOS!$C$1:$Z$1,0))="Consolidado")+--(INDEX(NORMATIVOS!$C$121:$Z$121,1,MATCH($B$3,NORMATIVOS!$C$1:$Z$1,0))="Consolidado") -> 9 | F13: =--(INDEX(NORMATIVOS!$C$107:$Z$107,1,MATCH($B$3,NORMATIVOS!$C$1:$Z$1,0))="En proceso")+--(INDEX(NORMATIVOS!$C$108:$Z$108,1,MATCH($B$3,NORMATIVOS!$C$1:$Z$1,0))="En proceso")+--(INDEX(NORMATIVOS!$C$109:$Z$109,1,MATCH($B$3,NORMATIVOS!$C$1:$Z$1,0))="En proceso")+--(INDEX(NORMATIVOS!$C$110:$Z$110,1,MATCH($B$3,NORMATIVOS!$C$1:$Z$1,0))="En proceso")+--(INDEX(NORMATIVOS!$C$111:$Z$111,1,MATCH($B$3,NORMATIVOS!$C$1:$Z$1,0))="En proceso")+--(INDEX(NORMATIVOS!$C$112:$Z$112,1,MATCH($B$3,NORMATIVOS!$C$1:$Z$1,0))="En proceso")+--(INDEX(NORMATIVOS!$C$113:$Z$113,1,MATCH($B$3,NORMATIVOS!$C$1:$Z$1,0))="En proceso")+--(INDEX(NORMATIVOS!$C$114:$Z$114,1,MATCH($B$3,NORMATIVOS!$C$1:$Z$1,0))="En proceso")+--(INDEX(NORMATIVOS!$C$115:$Z$115,1,MATCH($B$3,NORMATIVOS!$C$1:$Z$1,0))="En proceso")+--(INDEX(NORMATIVOS!$C$116:$Z$116,1,MATCH($B$3,NORMATIVOS!$C$1:$Z$1,0))="En proceso")+--(INDEX(NORMATIVOS!$C$117:$Z$117,1,MATCH($B$3,NORMATIVOS!$C$1:$Z$1,0))="En proceso")+--(INDEX(NORMATIVOS!$C$118:$Z$118,1,MATCH($B$3,NORMATIVOS!$C$1:$Z$1,0))="En proceso")+--(INDEX(NORMATIVOS!$C$119:$Z$119,1,MATCH($B$3,NORMATIVOS!$C$1:$Z$1,0))="En proceso")+--(INDEX(NORMATIVOS!$C$120:$Z$120,1,MATCH($B$3,NORMATIVOS!$C$1:$Z$1,0))="En proceso")+--(INDEX(NORMATIVOS!$C$121:$Z$121,1,MATCH($B$3,NORMATIVOS!$C$1:$Z$1,0))="En proceso") -> 3 | G13: =--(INDEX(NORMATIVOS!$C$107:$Z$107,1,MATCH($B$3,NORMATIVOS!$C$1:$Z$1,0))="Proyección")+--(INDEX(NORMATIVOS!$C$108:$Z$108,1,MATCH($B$3,NORMATIVOS!$C$1:$Z$1,0))="Proyección")+--(INDEX(NORMATIVOS!$C$109:$Z$109,1,MATCH($B$3,NORMATIVOS!$C$1:$Z$1,0))="Proyección")+--(INDEX(NORMATIVOS!$C$110:$Z$110,1,MATCH($B$3,NORMATIVOS!$C$1:$Z$1,0))="Proyección")+--(INDEX(NORMATIVOS!$C$111:$Z$111,1,MATCH($B$3,NORMATIVOS!$C$1:$Z$1,0))="Proyección")+--(INDEX(NORMATIVOS!$C$112:$Z$112,1,MATCH($B$3,NORMATIVOS!$C$1:$Z$1,0))="Proyección")+--(INDEX(NORMATIVOS!$C$113:$Z$113,1,MATCH($B$3,NORMATIVOS!$C$1:$Z$1,0))="Proyección")+--(INDEX(NORMATIVOS!$C$114:$Z$114,1,MATCH($B$3,NORMATIVOS!$C$1:$Z$1,0))="Proyección")+--(INDEX(NORMATIVOS!$C$115:$Z$115,1,MATCH($B$3,NORMATIVOS!$C$1:$Z$1,0))="Proyección")+--(INDEX(NORMATIVOS!$C$116:$Z$116,1,MATCH($B$3,NORMATIVOS!$C$1:$Z$1,0))="Proyección")+--(INDEX(NORMATIVOS!$C$117:$Z$117,1,MATCH($B$3,NORMATIVOS!$C$1:$Z$1,0))="Proyección")+--(INDEX(NORMATIVOS!$C$118:$Z$118,1,MATCH($B$3,NORMATIVOS!$C$1:$Z$1,0))="Proyección")+--(INDEX(NORMATIVOS!$C$119:$Z$119,1,MATCH($B$3,NORMATIVOS!$C$1:$Z$1,0))="Proyección")+--(INDEX(NORMATIVOS!$C$120:$Z$120,1,MATCH($B$3,NORMATIVOS!$C$1:$Z$1,0))="Proyección")+--(INDEX(NORMATIVOS!$C$121:$Z$121,1,MATCH($B$3,NORMATIVOS!$C$1:$Z$1,0))="Proyección") -> 3 | H13: =IFERROR(E13/(E13+F13+G13),0) -> 0.6
D14: ELEMENTOS DE VUELO | E14: =--(INDEX(NORMATIVOS!$C$122:$Z$122,1,MATCH($B$3,NORMATIVOS!$C$1:$Z$1,0))="Consolidado")+--(INDEX(NORMATIVOS!$C$123:$Z$123,1,MATCH($B$3,NORMATIVOS!$C$1:$Z$1,0))="Consolidado")+--(INDEX(NORMATIVOS!$C$124:$Z$124,1,MATCH($B$3,NORMATIVOS!$C$1:$Z$1,0))="Consolidado")+--(INDEX(NORMATIVOS!$C$125:$Z$125,1,MATCH($B$3,NORMATIVOS!$C$1:$Z$1,0))="Consolidado")+--(INDEX(NORMATIVOS!$C$126:$Z$126,1,MATCH($B$3,NORMATIVOS!$C$1:$Z$1,0))="Consolidado")+--(INDEX(NORMATIVOS!$C$127:$Z$127,1,MATCH($B$3,NORMATIVOS!$C$1:$Z$1,0))="Consolidado")+--(INDEX(NORMATIVOS!$C$128:$Z$128,1,MATCH($B$3,NORMATIVOS!$C$1:$Z$1,0))="Consolidado")+--(INDEX(NORMATIVOS!$C$129:$Z$129,1,MATCH($B$3,NORMATIVOS!$C$1:$Z$1,0))="Consolidado")+--(INDEX(NORMATIVOS!$C$130:$Z$130,1,MATCH($B$3,NORMATIVOS!$C$1:$Z$1,0))="Consolidado")+--(INDEX(NORMATIVOS!$C$131:$Z$131,1,MATCH($B$3,NORMATIVOS!$C$1:$Z$1,0))="Consolidado")+--(INDEX(NORMATIVOS!$C$132:$Z$132,1,MATCH($B$3,NORMATIVOS!$C$1:$Z$1,0))="Consolidado")+--(INDEX(NORMATIVOS!$C$133:$Z$133,1,MATCH($B$3,NORMATIVOS!$C$1:$Z$1,0))="Consolidado")+--(INDEX(NORMATIVOS!$C$134:$Z$134,1,MATCH($B$3,NORMATIVOS!$C$1:$Z$1,0))="Consolidado")+--(INDEX(NORMATIVOS!$C$135:$Z$135,1,MATCH($B$3,NORMATIVOS!$C$1:$Z$1,0))="Consolidado")+--(INDEX(NORMATIVOS!$C$136:$Z$136,1,MATCH($B$3,NORMATIVOS!$C$1:$Z$1,0))="Consolidado")+--(INDEX(NORMATIVOS!$C$137:$Z$137,1,MATCH($B$3,NORMATIVOS!$C$1:$Z$1,0))="Consolidado")+--(INDEX(NORMATIVOS!$C$138:$Z$138,1,MATCH($B$3,NORMATIVOS!$C$1:$Z$1,0))="Consolidado")+--(INDEX(NORMATIVOS!$C$139:$Z$139,1,MATCH($B$3,NORMATIVOS!$C$1:$Z$1,0))="Consolidado")+--(INDEX(NORMATIVOS!$C$140:$Z$140,1,MATCH($B$3,NORMATIVOS!$C$1:$Z$1,0))="Consolidado")+--(INDEX(NORMATIVOS!$C$141:$Z$141,1,MATCH($B$3,NORMATIVOS!$C$1:$Z$1,0))="Consolidado") -> 5 | F14: =--(INDEX(NORMATIVOS!$C$122:$Z$122,1,MATCH($B$3,NORMATIVOS!$C$1:$Z$1,0))="En proceso")+--(INDEX(NORMATIVOS!$C$123:$Z$123,1,MATCH($B$3,NORMATIVOS!$C$1:$Z$1,0))="En proceso")+--(INDEX(NORMATIVOS!$C$124:$Z$124,1,MATCH($B$3,NORMATIVOS!$C$1:$Z$1,0))="En proceso")+--(INDEX(NORMATIVOS!$C$125:$Z$125,1,MATCH($B$3,NORMATIVOS!$C$1:$Z$1,0))="En proceso")+--(INDEX(NORMATIVOS!$C$126:$Z$126,1,MATCH($B$3,NORMATIVOS!$C$1:$Z$1,0))="En proceso")+--(INDEX(NORMATIVOS!$C$127:$Z$127,1,MATCH($B$3,NORMATIVOS!$C$1:$Z$1,0))="En proceso")+--(INDEX(NORMATIVOS!$C$128:$Z$128,1,MATCH($B$3,NORMATIVOS!$C$1:$Z$1,0))="En proceso")+--(INDEX(NORMATIVOS!$C$129:$Z$129,1,MATCH($B$3,NORMATIVOS!$C$1:$Z$1,0))="En proceso")+--(INDEX(NORMATIVOS!$C$130:$Z$130,1,MATCH($B$3,NORMATIVOS!$C$1:$Z$1,0))="En proceso")+--(INDEX(NORMATIVOS!$C$131:$Z$131,1,MATCH($B$3,NORMATIVOS!$C$1:$Z$1,0))="En proceso")+--(INDEX(NORMATIVOS!$C$132:$Z$132,1,MATCH($B$3,NORMATIVOS!$C$1:$Z$1,0))="En proceso")+--(INDEX(NORMATIVOS!$C$133:$Z$133,1,MATCH($B$3,NORMATIVOS!$C$1:$Z$1,0))="En proceso")+--(INDEX(NORMATIVOS!$C$134:$Z$134,1,MATCH($B$3,NORMATIVOS!$C$1:$Z$1,0))="En proceso")+--(INDEX(NORMATIVOS!$C$135:$Z$135,1,MATCH($B$3,NORMATIVOS!$C$1:$Z$1,0))="En proceso")+--(INDEX(NORMATIVOS!$C$136:$Z$136,1,MATCH($B$3,NORMATIVOS!$C$1:$Z$1,0))="En proceso")+--(INDEX(NORMATIVOS!$C$137:$Z$137,1,MATCH($B$3,NORMATIVOS!$C$1:$Z$1,0))="En proceso")+--(INDEX(NORMATIVOS!$C$138:$Z$138,1,MATCH($B$3,NORMATIVOS!$C$1:$Z$1,0))="En proceso")+--(INDEX(NORMATIVOS!$C$139:$Z$139,1,MATCH($B$3,NORMATIVOS!$C$1:$Z$1,0))="En proceso")+--(INDEX(NORMATIVOS!$C$140:$Z$140,1,MATCH($B$3,NORMATIVOS!$C$1:$Z$1,0))="En proceso")+--(INDEX(NORMATIVOS!$C$141:$Z$141,1,MATCH($B$3,NORMATIVOS!$C$1:$Z$1,0))="En proceso") -> 8 | G14: =--(INDEX(NORMATIVOS!$C$122:$Z$122,1,MATCH($B$3,NORMATIVOS!$C$1:$Z$1,0))="Proyección")+--(INDEX(NORMATIVOS!$C$123:$Z$123,1,MATCH($B$3,NORMATIVOS!$C$1:$Z$1,0))="Proyección")+--(INDEX(NORMATIVOS!$C$124:$Z$124,1,MATCH($B$3,NORMATIVOS!$C$1:$Z$1,0))="Proyección")+--(INDEX(NORMATIVOS!$C$125:$Z$125,1,MATCH($B$3,NORMATIVOS!$C$1:$Z$1,0))="Proyección")+--(INDEX(NORMATIVOS!$C$126:$Z$126,1,MATCH($B$3,NORMATIVOS!$C$1:$Z$1,0))="Proyección")+--(INDEX(NORMATIVOS!$C$127:$Z$127,1,MATCH($B$3,NORMATIVOS!$C$1:$Z$1,0))="Proyección")+--(INDEX(NORMATIVOS!$C$128:$Z$128,1,MATCH($B$3,NORMATIVOS!$C$1:$Z$1,0))="Proyección")+--(INDEX(NORMATIVOS!$C$129:$Z$129,1,MATCH($B$3,NORMATIVOS!$C$1:$Z$1,0))="Proyección")+--(INDEX(NORMATIVOS!$C$130:$Z$130,1,MATCH($B$3,NORMATIVOS!$C$1:$Z$1,0))="Proyección")+--(INDEX(NORMATIVOS!$C$131:$Z$131,1,MATCH($B$3,NORMATIVOS!$C$1:$Z$1,0))="Proyección")+--(INDEX(NORMATIVOS!$C$132:$Z$132,1,MATCH($B$3,NORMATIVOS!$C$1:$Z$1,0))="Proyección")+--(INDEX(NORMATIVOS!$C$133:$Z$133,1,MATCH($B$3,NORMATIVOS!$C$1:$Z$1,0))="Proyección")+--(INDEX(NORMATIVOS!$C$134:$Z$134,1,MATCH($B$3,NORMATIVOS!$C$1:$Z$1,0))="Proyección")+--(INDEX(NORMATIVOS!$C$135:$Z$135,1,MATCH($B$3,NORMATIVOS!$C$1:$Z$1,0))="Proyección")+--(INDEX(NORMATIVOS!$C$136:$Z$136,1,MATCH($B$3,NORMATIVOS!$C$1:$Z$1,0))="Proyección")+--(INDEX(NORMATIVOS!$C$137:$Z$137,1,MATCH($B$3,NORMATIVOS!$C$1:$Z$1,0))="Proyección")+--(INDEX(NORMATIVOS!$C$138:$Z$138,1,MATCH($B$3,NORMATIVOS!$C$1:$Z$1,0))="Proyección")+--(INDEX(NORMATIVOS!$C$139:$Z$139,1,MATCH($B$3,NORMATIVOS!$C$1:$Z$1,0))="Proyección")+--(INDEX(NORMATIVOS!$C$140:$Z$140,1,MATCH($B$3,NORMATIVOS!$C$1:$Z$1,0))="Proyección")+--(INDEX(NORMATIVOS!$C$141:$Z$141,1,MATCH($B$3,NORMATIVOS!$C$1:$Z$1,0))="Proyección") -> 7 | H14: =IFERROR(E14/(E14+F14+G14),0) -> 0.25
D15: ACCIONES SIN TABLA DE SALTO | E15: =--(INDEX(NORMATIVOS!$C$144:$Z$144,1,MATCH($B$3,NORMATIVOS!$C$1:$Z$1,0))="Consolidado")+--(INDEX(NORMATIVOS!$C$145:$Z$145,1,MATCH($B$3,NORMATIVOS!$C$1:$Z$1,0))="Consolidado")+--(INDEX(NORMATIVOS!$C$146:$Z$146,1,MATCH($B$3,NORMATIVOS!$C$1:$Z$1,0))="Consolidado")+--(INDEX(NORMATIVOS!$C$147:$Z$147,1,MATCH($B$3,NORMATIVOS!$C$1:$Z$1,0))="Consolidado")+--(INDEX(NORMATIVOS!$C$148:$Z$148,1,MATCH($B$3,NORMATIVOS!$C$1:$Z$1,0))="Consolidado")+--(INDEX(NORMATIVOS!$C$149:$Z$149,1,MATCH($B$3,NORMATIVOS!$C$1:$Z$1,0))="Consolidado")+--(INDEX(NORMATIVOS!$C$150:$Z$150,1,MATCH($B$3,NORMATIVOS!$C$1:$Z$1,0))="Consolidado") -> 7 | F15: =--(INDEX(NORMATIVOS!$C$144:$Z$144,1,MATCH($B$3,NORMATIVOS!$C$1:$Z$1,0))="En proceso")+--(INDEX(NORMATIVOS!$C$145:$Z$145,1,MATCH($B$3,NORMATIVOS!$C$1:$Z$1,0))="En proceso")+--(INDEX(NORMATIVOS!$C$146:$Z$146,1,MATCH($B$3,NORMATIVOS!$C$1:$Z$1,0))="En proceso")+--(INDEX(NORMATIVOS!$C$147:$Z$147,1,MATCH($B$3,NORMATIVOS!$C$1:$Z$1,0))="En proceso")+--(INDEX(NORMATIVOS!$C$148:$Z$148,1,MATCH($B$3,NORMATIVOS!$C$1:$Z$1,0))="En proceso")+--(INDEX(NORMATIVOS!$C$149:$Z$149,1,MATCH($B$3,NORMATIVOS!$C$1:$Z$1,0))="En proceso")+--(INDEX(NORMATIVOS!$C$150:$Z$150,1,MATCH($B$3,NORMATIVOS!$C$1:$Z$1,0))="En proceso") -> 0 | G15: =--(INDEX(NORMATIVOS!$C$144:$Z$144,1,MATCH($B$3,NORMATIVOS!$C$1:$Z$1,0))="Proyección")+--(INDEX(NORMATIVOS!$C$145:$Z$145,1,MATCH($B$3,NORMATIVOS!$C$1:$Z$1,0))="Proyección")+--(INDEX(NORMATIVOS!$C$146:$Z$146,1,MATCH($B$3,NORMATIVOS!$C$1:$Z$1,0))="Proyección")+--(INDEX(NORMATIVOS!$C$147:$Z$147,1,MATCH($B$3,NORMATIVOS!$C$1:$Z$1,0))="Proyección")+--(INDEX(NORMATIVOS!$C$148:$Z$148,1,MATCH($B$3,NORMATIVOS!$C$1:$Z$1,0))="Proyección")+--(INDEX(NORMATIVOS!$C$149:$Z$149,1,MATCH($B$3,NORMATIVOS!$C$1:$Z$1,0))="Proyección")+--(INDEX(NORMATIVOS!$C$150:$Z$150,1,MATCH($B$3,NORMATIVOS!$C$1:$Z$1,0))="Proyección") -> 0 | H15: =IFERROR(E15/(E15+F15+G15),0) -> 1
